Workbook

Sheet Welcome Page
B3: Welcome!
B4: to the Amazing Race (US) data spreadsheet
B5: Created by wavesei (Sam)
B7: Backstory:
B8: When I was in college, I somehow found myself addicted to the Amazing Race (TAR). I was facinated with the traveling, storylines, and amazing moments throughout, and I knew that it was new dream of my to be on the show. To be able to take part in the most compelling reality show of all time, to take part of my own storyline, to hear Phil say that I'm team number 1. Anyways, I was watching old seasons, when I noticed that there are many similarities between seasons, and I became obsessed with tracking how each season/race was ran. I was never much of a stats guy, but I wanted to be in the mind of the show's creators, in case I ever get the oppotunity to take part in this race that so many love. I began "logging" each season of the race in composition notebooks. I have some scans of a few pages below, including my first and last page. In these entries with my God-awful handwriting, I would log what season it was at the top and separate each leg, normally fitting two on a page. I also dated each entry, to track my progress. Each leg would note where racers traveled to (normally incorrectly), if the leg was elimination or not, what type of clue was read for each challenge, a brief description of each challenge, twists that happened, who got eliminated/saved from elimination and briefly why, and what keywords were seen in this leg. I invented these keywords as I noticed similarities between seasons, to see how the building blocks of the race changed over time. I started this journey of watching and logging each season of TAR in June 2021 with Season 32, and finished this month, July 2024 with Season 35. Yes, it took me three years. Sometimes life got busy with work and school, but I watched and logged when I could. In this process I would mostly work backwards, but sometimes jumped all over the place. Truthfully I do not specifically remember when 20-year-old me decided to start this, but I'm glad I saw this project through to completion, and I imagine some cool stuff can be done with this data. I should note that to properly understand this spreadsheet, you have seen at least one episode of TAR, hopefully an entire season. I tried to explain everything for the casual viewer, but I'm sure there is necessary detail this spreadsheet is lacking for someone who has never watched TAR before to understand. I would first start with reading "Sheets Information", to see what each tab is meant for, or just click whatever it's your life. I'm sure that over this three-year-process I made plenty of mistakes, and if you notice any while viewing this document, please reach out and let me know! Obviously, I want this spreadsheet to be as accurate as possible. Huge thank you to Wikipedia and TAR Wiki on making data on the race so easily accessible. Happy viewing!
B46: Sheets Information:
B47: Logs | D47: This is where the physical logging (on paper) was translated to. Each season's challenges, eliminations, twists, keywords, locations, and winners are logged.
B48: Keywords | D48: Each keyword is explained when and why they are used, and tracked for use in each season.
B49: Race Locations | D49: The countries and geographical areas ran to in each leg of every season are listed here, and each country and area is tracked per leg and in totality. Maps for each season of the race are also included.
B50: Challenges | D50: This sheet tracks the total amount of challenges in each season, and explains the niche challenges in certain seasons, such as the Hazard.
B51: Route Info | D51: Dedicated to tracking the amount of Route Info challenges per season.
B52: Road Block | D52: Dedicated to tracking the amount of Road Block challenges per season.
B53: Detour | D53: Dedicated to tracking the amount of Detour challenges per season.
B54: Fast Forward | D54: Dedicated to tracking the amount of Fast Forward challenges per season.
B55: Speed Bump | D55: Dedicated to tracking the amount of Speed Bump challenges per season.
B56: Leg-by-Leg | D56: This sheet is for tracking the amount of each challenge type for every leg of every season, then examining them in totality.
B57: Challenge-by-Challenge | D57: This sheet is for tracking the amount of each challenge for every challenge on every leg of every season, then examining them in totality.
B58: Leg-by-Challenge | D58: This sheet is for tracking the amount of challenge per leg.
... B67: Season 37 | D67: The actual most-recently filmed season of the race, this sheet also examines how it is different from past seasons.
B69: Notes for the Future:
B70: There are some things that I wish to add to this spreadsheet in the future, in the goal of tracking every piece of data in TAR:
B72: - Money given at the start of each leg
B73: - Adding in common triggers for each episode
B74: - More statistics and tracking of changes over the course of TAR (again, I've never been much for stats).
B75: - Start Times
B76: - Track the amount of miles traveled per Season
B77: - Detour twists (blind Detours, e.g.)

Sheet Logs
B4: Season Logs
K5: Template way over there -->
B6: Season 1 | BT6: Season Template
B7: Winners = Rob and Brennan | E7: Filmed: 3/8/01 - 4/8/01 | Q7: Keywords | BT7: Winners = | BW7: Filmed: | CI7: Keywords
B8: Challenges | C8: Leg 1 | D8: Leg 2 | E8: Leg 3 | F8: Leg 4 | G8: Leg 5 | H8: Leg 6 | I8: Leg 7 | J8: Leg 8 | K8: Leg 9 | L8: Leg 10 | M8: Leg 11 | N8: Leg 12 | O8: Leg 13 | Q8: Leg 1 | R8: Leg 2 | S8: Leg 3 | T8: Leg 4 | U8: Leg 5 | V8: Leg 6 | W8: Leg 7 | X8: Leg 8 | Y8: Leg 9 | Z8: Leg 10 | AA8: Leg 11 | AB8: Leg 12 | AC8: Leg 13 | BT8: Challenges | BU8: Leg 1 | BV8: Leg 2 | BW8: Leg 3 | BX8: Leg 4 | BY8: Leg 5 | BZ8: Leg 6 | CA8: Leg 7 | CB8: Leg 8 | CC8: Leg 9 | CD8: Leg 10 | CE8: Leg 11 | CF8: Leg 12 | CG8: Leg 13 | CI8: Leg 1 | CJ8: Leg 2 | CK8: Leg 3 | CL8: Leg 4 | CM8: Leg 5 | CN8: Leg 6 | CO8: Leg 7 | CP8: Leg 8 | CQ8: Leg 9 | CR8: Leg 10 | CS8: Leg 11 | CT8: Leg 12 | CU8: Leg 13
B9: 1 | C9: Route Info | D9: Fast Forward | E9: Fast Forward | F9: Fast Forward | G9: Fast Forward | H9: Route Info | I9: Fast Forward | J9: Route Info | K9: Fast Forward | L9: Fast Forward | M9: Fast Forward | N9: Route Info | O9: Route Info | Q9: Driving | R9: Travel Issues | S9: Language | T9: Flags | U9: Driving | V9: Searching | W9: Searching | X9: Searching | Y9: Counting | Z9: Physical Strength | AA9: Hand Eye Coordination | AB9: Physical Strength | AC9: Physical Strength | BT9: 1
B10: 2 | C10: Route Info | D10: Route Info | E10: Route Info | F10: Route Info | G10: Route Info | H10: Fast Forward | I10: Detour | J10: Fast Forward | K10: Route Info | L10: Route Info | M10: Route Info | N10: Route Info | O10: Detour | Q10: Travel Issues | R10: Physical Strength | S10: Physical Strength | T10: Travel Issues | U10: Puzzle | V10: Travel Issues | W10: Biking | X10: Animals | Y10: Searching | Z10: Travel Issues | AA10: Language | AB10: Searching | AC10: Animals | BT10: 2
B11: 3 | C11: Fast Forward | D11: Detour | E11: Detour | F11: Detour | G11: Detour | H11: Route Info | I11: Route Info | J11: Route Info | K11: Detour | L11: Detour | M11: Detour | N11: Detour | O11: Road Block | Q11: Physical Strength | R11: Puzzle | T11: Searching | U11: Searching | V11: Driving | W11: Heights | X11: Travel Issues | Y11: Animals | Z11: Heights | AA11: Searching | AB11: Driving | AC11: Pain | BT11: 3
B12: 4 | C12: Route Info | D12: Route Info | E12: Route Info | F12: Route Info | G12: Route Info | H12: Detour | I12: Road Block | J12: Detour | K12: Road Block | L12: Route Info | M12: Route Info | N12: Route Info | O12: Route Info | Q12: Heights | R12: Driving | T12: Pain | U12: Animals | V12: Navigation | W12: Navigation | Z12: Searching | AA12: Food | AB12: Travel Issues | BT12: 4
B13: 5 | C13: Detour | D13: Road Block | E13: Road Block | F13: Road Block | G13: Road Block | H13: Route Info | I13: Route Info | J13: Route Info | K13: Route Info | L13: Road Block | M13: Route Info | N13: Route Info | O13: Route Info | R13: Searching | T13: Animals | U13: Physical Strength | W13: Travel Issues | Z13: Swimming | AA13: Travel Issues | BT13: 5
B14: 6 | C14: Route Info | E14: Route Info | G14: Route Info | H14: Road Block | J14: Road Block | L14: Route Info | M14: Road Block | N14: Route Info | U14: Navigation | BT14: 6
B15: 7 | J15: Route Info | L15: Route Info | N15: Road Block | BT15: 7
B16: 8 | N16: Route Info | BT16: 8
B17: 9 | Q17: Destinations | BT17: 9 | CI17: Destinations
B18: 10 | Q18: Leg 1 | R18: Leg 2 | S18: Leg 3 | T18: Leg 4 | U18: Leg 5 | V18: Leg 6 | W18: Leg 7 | X18: Leg 8 | Y18: Leg 9 | Z18: Leg 10 | AA18: Leg 11 | AB18: Leg 12 | AC18: Leg 13 | BT18: 10 | CI18: Leg 1 | CJ18: Leg 2 | CK18: Leg 3 | CL18: Leg 4 | CM18: Leg 5 | CN18: Leg 6 | CO18: Leg 7 | CP18: Leg 8 | CQ18: Leg 9 | CR18: Leg 10 | CS18: Leg 11 | CT18: Leg 12 | CU18: Leg 13
B19: Elimination? | C19: Yes | D19: Yes | E19: Yes | F19: Yes | G19: Yes | H19: No | I19: Yes | J19: No | K19: Yes | L19: No | M19: Yes | N19: No | O19: Final Leg | Q19: NYC, USA | R19: Livingston District, Zambia | S19: Paris, France | T19: Les Baux-de-Provence, France | U19: El Djem, Tunisia | V19: Gabes, Tunisia | W19: Sant'Agata Bolognese, Italy | X19: Agra, India | Y19: Bikaner, India | Z19: Krabi, Thailand | AA19: Ao Nang, Thailand | AB19: Beijing, China | AC19: Trapper Creek, USA | BT19: Elimination?
Q20: Livingston, Zambia | R20: Mosi-oa-Tunya Nat'l Park, Zambia | S20: Les Baux-de-Provence, France | T20: Tunis, Tunisia | U20: Tatouine, Tunisia | V20: La Marsa, Tunisia | W20: Ferrara, Italy | X20: Jaipur, India | Y20: Bangkok, Thailand | Z20: Ao Phang Nga Nat'l Park, Thailand | AA20: Beijing, China | AB20: Scotty Lake, USA | AC20: Talkeetna, USA | BT20: U-Turn/Yield?
Q21: Mosi-oa-Tunya Nat'l Park, Zambia | R21: Paris, France | T21: El Djem, Tunisia | U21: Jebil Nat'l Park, Tunisia | V21: Rome, Italy | W21: Delhi, India | X21: Amber, India | Y21: Kanchanaburi, Thailand | Z21: Ao Nang, Thailand | AB21: Glacier View, USA | AC21: NYC, USA | BT21: Express Pass/Safe?
Q22: Livingston District, Zambia | V22: San Cesario sul Panaro, Italy | W22: Agra, India | X22: Deshnoke, India | Y22: Krabi, Thailand | AB22: Trapper Creek, USA
V23: Sant'Agata Bolognese, Italy | X23: Bikaner, India
B24: Season 2
B25: Winners = Chris and Alex | E25: Filmed: 1/7/02 - 3/3/02 | Q25: Keywords
B26: Challenges | C26: Leg 1 | D26: Leg 2 | E26: Leg 3 | F26: Leg 4 | G26: Leg 5 | H26: Leg 6 | I26: Leg 7 | J26: Leg 8 | K26: Leg 9 | L26: Leg 10 | M26: Leg 11 | N26: Leg 12 | O26: Leg 13 | Q26: Leg 1 | R26: Leg 2 | S26: Leg 3 | T26: Leg 4 | U26: Leg 5 | V26: Leg 6 | W26: Leg 7 | X26: Leg 8 | Y26: Leg 9 | Z26: Leg 10 | AA26: Leg 11 | AB26: Leg 12 | AC26: Leg 13
B27: 1 | C27: Route Info | D27: Route Info | E27: Route Info | F27: Route Info | G27: Fast Forward | H27: Fast Forward | I27: Route Info | J27: Fast Forward | K27: Fast Forward | L27: Fast Forward | M27: Route Info | N27: Route Info | O27: Route Info | Q27: Driving | R27: Hand Eye Coordination | S27: Dancing | T27: Driving | U27: Travel Issues | V27: Searching | W27: Searching | X27: Physical Strength | Y27: Heights | Z27: Driving | AA27: Driving | AB27: Driving | AC27: Driving
B28: 2 | C28: Route Info | D28: Fast Forward | E28: Fast Forward | F28: Route Info | G28: Route Info | H28: Route Info | I28: Route Info | J28: Route Info | K28: Route Info | L28: Route Info | M28: Fast Forward | N28: Route Info | O28: Route Info | Q28: Heights | R28: Heights | S28: Selling | T28: Searching | U28: Searching | V28: Travel Issues | W28: Driving | X28: Language | Y28: Driving | Z28: Heights | AA28: Travel Issues | AB28: Searching | AC28: Physical Strength
B29: 3 | C29: Fast Forward | D29: Route Info | E29: Route Info | F29: Fast Forward | G29: Detour | H29: Detour | I29: Fast Forward | J29: Route Info | K29: Route Info | L29: Route Info | M29: Route Info | N29: Route Info | O29: Route Info | Q29: Searching | R29: Searching | S29: Travel Issues | T29: Physical Strength | V29: Driving | W29: Food | Y29: Food | Z29: Physical Strength | AA29: Heights | AB29: Biking
B30: 4 | C30: Route Info | D30: Detour | E30: Detour | F30: Route Info | G30: Route Info | H30: Route Info | I30: Route Info | J30: Detour | K30: Detour | L30: Detour | M30: Detour | N30: Detour | O30: Route Info | Q30: Travel Issues | R30: Driving | S30: Food | T30: Swimming | V30: Balance | W30: Travel Issues | Y30: Searching | Z30: Travel Issues | AA30: Physical Strength | AB30: Swimming
B31: 5 | C31: Detour | D31: Route Info | E31: Route Info | F31: Route Info | G31: Road Block | H31: Road Block | I31: Detour | J31: Route Info | K31: Route Info | L31: Route Info | M31: Route Info | N31: Route Info | O31: Route Info | R31: Travel Issues | T31: Travel Issues | V31: Physical Strength | W31: Hand Eye Coordination | Y31: Physical Strength | Z31: Animals | AB31: Physical Strength
B32: 6 | C32: Route Info | D32: Route Info | E32: Road Block | F32: Detour | G32: Route Info | H32: Route Info | I32: Route Info | J32: Road Block | K32: Road Block | L32: Road Block | M32: Road Block | N32: Road Block | O32: Route Info | R32: Physical Strength | V32: Animals | Y32: Hand Eye Coordination | AB32: Travel Issues
B33: 7 | D33: Road Block | F33: Route Info | I33: Road Block | J33: Route Info | K33: Route Info | M33: Route Info | N33: Route Info | O33: Road Block
B34: 8 | D34: Route Info | F34: Route Info | I34: Route Info | O34: Route Info
B35: 9 | F35: Road Block | O35: Route Info | Q35: Destinations
B36: 10 | F36: Route Info | Q36: Leg 1 | R36: Leg 2 | S36: Leg 3 | T36: Leg 4 | U36: Leg 5 | V36: Leg 6 | W36: Leg 7 | X36: Leg 8 | Y36: Leg 9 | Z36: Leg 10 | AA36: Leg 11 | AB36: Leg 12 | AC36: Leg 13
B37: Elimination? | C37: Yes | D37: Yes | E37: Yes | F37: Yes | G37: Yes | H37: No | I37: Yes | J37: No | K37: Yes | L37: No | M37: Yes | N37: No | O37: Final Leg | Q37: Pahrump, USA | R37: Rio de Janero, Brazil | S37: Foz do Iguacu, Brazil | T37: Stellenbosch, South Africa | U37: Windhock, Namibia | V37: Amphawa, Thailand | W37: Karen Village, Thailand | X37: Hong Kong, China | Y37: Sydney, Australia | Z37: Coober Pedy, Australia | AA37: Cantaburry Plains, New Zealand | AB37: Auckland, New Zealand | AC37: Maui, USA
Q38: Rio de Janero, Brazil | R38: Foz do Iguacu, Brazil | S38: Capetown, South Africa | T38: Walvis Bay, Namibia | U38: Bankok, Thailand | V38: Bankok, Thailand | W38: Chiang Mai, Thailand | X38: Sydney, Australia | Y38: Coober Pedy, Australia | Z38: Queenstown, New Zealand | AA38: Rotorua, New Zealand | AB38: Maui, USA | AC38: Hana Bay, USA
S39: Stellenbosch, South Africa | T39: Swakopmund, Namibia | U39: Ratchaburi, Thaliand | V39: Mongou, Thailand | W39: Hong Kong, China | Z39: Gibbston, New Zealand | AA39: Waitomo Caves, New Zealand | AC39: Anchorage, USA
T40: Spitzkopf, Namibia | U40: Amphawa, Thailand | V40: Mae Ping Village, Thailand | Z40: Cantaburry Plains, New Zealand | AA40: Auckland, New Zealand | AC40: Big Lake, USA
T41: Windhock, Namibia | V41: Karen Village, Thailand | AC41: San Fran, USA
B42: Season 3
B43: Winners = Flo and Zach | E43: Filmed: 8/9/02 - 9/8/02 | Q43: Keywords
...

Sheet SQL_Data
A1: Season_Num | B1: Leg_Num | C1: Challenge_1 | D1: Challenge_2 | E1: Challenge_3 | F1: Challenge_4 | G1: Challenge_5 | H1: Challenge_6 | I1: Challenge_7 | J1: Challenge_8 | K1: Challenge_9 | L1: Challenge_10 | M1: Challenge_11 | N1: Challenge_12 | O1: Challenge_13
A2: 1 | B2: 1 | C2: Route Info | D2: Route Info | E2: Fast Forward | F2: Route Info | G2: Detour | H2: Route Info
A3: 1 | B3: 2 | C3: Fast Forward | D3: Route Info | E3: Detour | F3: Route Info | G3: Road Block | Q3: SQL Query Maker
A4: 1 | B4: 3 | C4: Fast Forward | D4: Route Info | E4: Detour | F4: Route Info | G4: Road Block | H4: Route Info | Q4: In each of the dropdowns, either select an option, or leave it blank! SQL will show a list below that meets the requirements you specified. This Query tracks challenges, locations, eliminations, and twists for each season and leg. If your selections have not happened before, the query will return blank. If all the dropdowns are left blank, then information from every leg will return.
A5: 1 | B5: 4 | C5: Fast Forward | D5: Route Info | E5: Detour | F5: Route Info | G5: Road Block | Q5: Season # | R5: Leg # | S5: Challenge 1 | T5: Challenge 2 | U5: Challenge 3 | V5: Challenge 4 | W5: Challenge 5 | X5: Challenge 6 | Y5: Challenge 7 | Z5: Challenge 8 | AA5: Challenge 9 | AB5: Challenge 10 | AC5: Challenge 11 | AD5: Challenge 12 | AE5: Challenge 13 | AF5: Country | AG5: Area of World | AH5: Elimination | AI5: Twist
A6: 1 | B6: 5 | C6: Fast Forward | D6: Route Info | E6: Detour | F6: Route Info | G6: Road Block | H6: Route Info
A7: 1 | B7: 6 | C7: Route Info | D7: Fast Forward | E7: Route Info | F7: Detour | G7: Route Info | H7: Road Block | P7: {=_xldudf_SQLOOKUP(_xlfn._LONGTEXT(" SELECT challenges.Season_Num as 'Season #', challenges.Leg_Num as 'Leg #', challenges.Challenge_1 as 'Challenge 1', challenges.Challenge_2 as 'Challenge 2', challenges.Challenge_3 as 'Challenge 3', challenges.Challenge_4 as 'Challenge 4', challenges.Cha","llenge_5 as 'Challenge 5', challenges.Challenge_6 as 'Challenge 6', challenges.Challenge_7 as 'Challenge 7', challenges.Challenge_8 as 'Challenge 8', challenges.Challenge_9 as 'Challenge 9', challenges.Challenge_10 as 'Challenge 10', challenges.Challenge_","11 as 'Challenge 11', challenges.Challenge_12 as 'Challenge 12', challenges.Challenge_13 as 'Challenge 13', locations.Country, locations.Geographic_Area as 'Area of World', elimination.Elimination, twists.Twist, twists.Challenge_Num as 'Twist Challenge #'",", winners.Winning_Team as 'Leg Winner' FROM challenges INNER JOIN locations ON challenges.Season_Num=locations.Season_Num AND challenges.Leg_Num=locations.Leg_Num INNER JOIN elimination ON challenges.Season_Num=elimination.Season_Num AND challenges.Leg_Nu","m=elimination.Leg_Num INNER JOIN twists ON challenges.Season_Num=twists.Season_Num AND challenges.Leg_Num=twists.Leg_Num INNER JOIN winners ON challenges.Season_Num=winners.Season_Num AND challenges.Leg_Num=winners.Leg_Num WHERE ('")&R6&"' = '' OR challenges.Leg_Num = '"&R6&"') AND ('"&Q6&"' = '' OR challenges.Season_Num = '"&Q6&"') AND ('"&S6&"' = '' OR challenges.Challenge_1 = '"&S6&"') AND ('"&T6&"' = '' OR challenges.Challenge_2 = '"&T6&"') AND ('"&U6&"' = '' OR challenges.Challenge_3 = '"&U6&"') AND ('"&V6&"' = '' OR challenges.Challenge_4 = '"&V6&"') AND ('"&W6&"' = '' OR challenges.Challenge_5 = '"&W6&"') AND ('"&X6&"' = '' OR challenges.Challenge_6 = '"&X6&"') AND ('"&Y6&"' = '' OR challenges.Challenge_7 = '"&Y6&"') AND ('"&Z6&"' = '' OR challenges.Challenge_8 = '"&Z6&"') AND ('"&AA6&"' = '' OR challenges.Challenge_9 = '"&AA6&"') AND ('"&AB6&"' = '' OR challenges.Challenge_10 = '"&AB6&"') AND ('"&AC6&"' = '' OR challenges.Challenge_11 = '"&AC6&"') AND ('"&AD6&"' = '' OR challenges.Challenge_12 = '"&AD6&"') AND ('"&AE6&"' = '' OR challenges.Challenge_13 = '"&AE6&"') AND ('"&AF6&"' = '' OR locations.Country = '"&AF6&"') AND ('"&AG6&"' = '' OR locations.Geographic_Area = '"&AG6&"') AND ('"&AH6&"' = '' OR elimination.Elimination = '"&AH6&"') AND ('"&AI6&"' = '' OR twists.Twist = '"&AI6&"')", "challenges", $A$1:$O$458, "locations", A460:D917, "elimination", A920:C1377, "twists", A1380:D1837, "winners", A1840:C2297)} -> Season # | Q7: Leg # | R7: Challenge 1 | S7: Challenge 2 | T7: Challenge 3 | U7: Challenge 4 | V7: Challenge 5 | W7: Challenge 6 | X7: Challenge 7 | Y7: Challenge 8 | Z7: Challenge 9 | AA7: Challenge 10 | AB7: Challenge 11 | AC7: Challenge 12 | AD7: Challenge 13 | AE7: Country | AF7: Area of World | AG7: Elimination | AH7: Twist | AI7: Twist Challenge # | AJ7: Leg Winner | AN7: {=_xldudf_SQLOOKUP(_xlfn._LONGTEXT("SELECT COUNT(*) as 'Your query returned this many legs:' FROM challenges INNER JOIN locations ON challenges.Season_Num=locations.Season_Num AND challenges.Leg_Num=locations.Leg_Num INNER JOIN elimination ON challenges.Season_Num=elimination.Season_Num AND"," challenges.Leg_Num=elimination.Leg_Num INNER JOIN twists ON challenges.Season_Num=twists.Season_Num AND challenges.Leg_Num=twists.Leg_Num INNER JOIN winners ON challenges.Season_Num=winners.Season_Num AND challenges.Leg_Num=winners.Leg_Num WHERE ('")&R6&"' = '' OR challenges.Leg_Num = '"&R6&"') AND ('"&Q6&"' = '' OR challenges.Season_Num = '"&Q6&"') AND ('"&S6&"' = '' OR challenges.Challenge_1 = '"&S6&"') AND ('"&T6&"' = '' OR challenges.Challenge_2 = '"&T6&"') AND ('"&U6&"' = '' OR challenges.Challenge_3 = '"&U6&"') AND ('"&V6&"' = '' OR challenges.Challenge_4 = '"&V6&"') AND ('"&W6&"' = '' OR challenges.Challenge_5 = '"&W6&"') AND ('"&X6&"' = '' OR challenges.Challenge_6 = '"&X6&"') AND ('"&Y6&"' = '' OR challenges.Challenge_7 = '"&Y6&"') AND ('"&Z6&"' = '' OR challenges.Challenge_8 = '"&Z6&"') AND ('"&AA6&"' = '' OR challenges.Challenge_9 = '"&AA6&"') AND ('"&AB6&"' = '' OR challenges.Challenge_10 = '"&AB6&"') AND ('"&AC6&"' = '' OR challenges.Challenge_11 = '"&AC6&"') AND ('"&AD6&"' = '' OR challenges.Challenge_12 = '"&AD6&"') AND ('"&AE6&"' = '' OR challenges.Challenge_13 = '"&AE6&"') AND ('"&AF6&"' = '' OR locations.Country = '"&AF6&"') AND ('"&AG6&"' = '' OR locations.Geographic_Area = '"&AG6&"') AND ('"&AH6&"' = '' OR elimination.Elimination = '"&AH6&"') AND ('"&AI6&"' = '' OR twists.Twist = '"&AI6&"')", "challenges", $A$1:$O$458, "locations", A460:D917, "elimination", A920:C1377, "twists", A1380:D1837, "winners", A1840:C2297)} -> Your query returned this many legs:
A8: 1 | B8: 7 | C8: Fast Forward | D8: Detour | E8: Route Info | F8: Road Block | G8: Route Info | P8: 1 | Q8: 1 | R8: Route Info | S8: Route Info | T8: Fast Forward | U8: Route Info | V8: Detour | W8: Route Info | AE8: Zambia | AF8: Southern Africa | AG8: Yes | AJ8: Rob & Brennan | AN8: 457
A9: 1 | B9: 8 | C9: Route Info | D9: Fast Forward | E9: Route Info | F9: Detour | G9: Route Info | H9: Road Block | I9: Route Info | P9: 1 | Q9: 2 | R9: Fast Forward | S9: Route Info | T9: Detour | U9: Route Info | V9: Road Block | AE9: France | AF9: Western Europe | AG9: Yes | AJ9: Pat & Brenda
A10: 1 | B10: 9 | C10: Fast Forward | D10: Route Info | E10: Detour | F10: Road Block | G10: Route Info | P10: 1 | Q10: 3 | R10: Fast Forward | S10: Route Info | T10: Detour | U10: Route Info | V10: Road Block | W10: Route Info | AE10: France | AF10: Western Europe | AG10: Yes | AJ10: Kevin & Drew
A11: 1 | B11: 10 | C11: Fast Forward | D11: Route Info | E11: Detour | F11: Route Info | G11: Road Block | H11: Route Info | I11: Route Info | P11: 1 | Q11: 4 | R11: Fast Forward | S11: Route Info | T11: Detour | U11: Route Info | V11: Road Block | AE11: Tunisia | AF11: Northern Africa | AG11: Yes | AJ11: Joe & Bill
A12: 1 | B12: 11 | C12: Fast Forward | D12: Route Info | E12: Detour | F12: Route Info | G12: Route Info | H12: Road Block | P12: 1 | Q12: 5 | R12: Fast Forward | S12: Route Info | T12: Detour | U12: Route Info | V12: Road Block | W12: Route Info | AE12: Tunisia | AF12: Northern Africa | AG12: Yes | AJ12: Kevin & Drew
A13: 1 | B13: 12 | C13: Route Info | D13: Route Info | E13: Detour | F13: Route Info | G13: Route Info | H13: Route Info | I13: Road Block | J13: Route Info | P13: 1 | Q13: 6 | R13: Route Info | S13: Fast Forward | T13: Route Info | U13: Detour | V13: Route Info | W13: Road Block | AE13: Italy | AF13: Southern Europe | AG13: No | AJ13: Frank & Margarita
A14: 1 | B14: Final | C14: Route Info | D14: Detour | E14: Road Block | F14: Route Info | G14: Route Info | P14: 1 | Q14: 7 | R14: Fast Forward | S14: Detour | T14: Route Info | U14: Road Block | V14: Route Info | AE14: India | AF14: South Asia | AG14: Yes | AJ14: Frank & Margarita
A15: 2 | B15: 1 | C15: Route Info | D15: Route Info | E15: Fast Forward | F15: Route Info | G15: Detour | H15: Route Info | P15: 1 | Q15: 8 | R15: Route Info | S15: Fast Forward | T15: Route Info | U15: Detour | V15: Route Info | W15: Road Block | X15: Route Info | AE15: India | AF15: South Asia | AG15: No | AJ15: Kevin & Drew
A16: 2 | B16: 2 | C16: Route Info | D16: Fast Forward | E16: Route Info | F16: Detour | G16: Route Info | H16: Route Info | I16: Road Block | J16: Route Info | P16: 1 | Q16: 9 | R16: Fast Forward | S16: Route Info | T16: Detour | U16: Road Block | V16: Route Info | AE16: Thailand | AF16: South East Asia | AG16: Yes | AJ16: Rob & Brennan
A17: 2 | B17: 3 | C17: Route Info | D17: Fast Forward | E17: Route Info | F17: Detour | G17: Route Info | H17: Road Block | P17: 1 | Q17: 10 | R17: Fast Forward | S17: Route Info | T17: Detour | U17: Route Info | V17: Road Block | W17: Route Info | X17: Route Info | AE17: Thailand | AF17: South East Asia | AG17: No | AJ17: Rob & Brennan
A18: 2 | B18: 4 | C18: Route Info | D18: Route Info | E18: Fast Forward | F18: Route Info | G18: Route Info | H18: Detour | I18: Route Info | J18: Route Info | K18: Road Block | L18: Route Info | P18: 1 | Q18: 11 | R18: Fast Forward | S18: Route Info | T18: Detour | U18: Route Info | V18: Route Info | W18: Road Block | AE18: China | AF18: East Asia | AG18: Yes | AJ18: Frank & Margarita
A19: 2 | B19: 5 | C19: Fast Forward | D19: Route Info | E19: Detour | F19: Route Info | G19: Road Block | H19: Route Info | P19: 1 | Q19: 12 | R19: Route Info | S19: Route Info | T19: Detour | U19: Route Info | V19: Route Info | W19: Route Info | X19: Road Block | Y19: Route Info | AE19: USA | AF19: North America | AG19: No | AJ19: Rob & Brennan | AQ19: Dropdown Lists
A20: 2 | B20: 6 | C20: Fast Forward | D20: Route Info | E20: Detour | F20: Route Info | G20: Road Block | H20: Route Info | P20: 1 | Q20: Final | R20: Route Info | S20: Detour | T20: Road Block | U20: Route Info | V20: Route Info | AE20: USA | AF20: North America | AG20: Final Leg | AJ20: Rob & Brennan | AP20: Season # | AQ20: Leg # | AR20: Challenge Type | AS20: Country | AT20: Area | AU20: Elimination | AV20: Twist
A21: 2 | B21: 7 | C21: Route Info | D21: Route Info | E21: Fast Forward | F21: Route Info | G21: Detour | H21: Route Info | I21: Road Block | J21: Route Info | P21: 2 | Q21: 1 | R21: Route Info | S21: Route Info | T21: Fast Forward | U21: Route Info | V21: Detour | W21: Route Info | AE21: Brazil | AF21: South America | AG21: Yes | AJ21: Tara & Wil | AP21: 1 | AQ21: 1 | AR21: Route Info | AS21: Argentina | AT21: Caribbean | AU21: Yes | AV21: Double U-Turn
A22: 2 | B22: 8 | C22: Fast Forward | D22: Route Info | E22: Route Info | F22: Detour | G22: Route Info | H22: Road Block | I22: Route Info | P22: 2 | Q22: 2 | R22: Route Info | S22: Fast Forward | T22: Route Info | U22: Detour | V22: Route Info | W22: Route Info | X22: Road Block | Y22: Route Info | AE22: Brazil | AF22: South America | AG22: Yes | AJ22: Shola & Doyin | AP22: 2 | AQ22: 2 | AR22: Road Block | AS22: Armenia | AT22: Central America | AU22: No | AV22: Driver's Seat
A23: 2 | B23: 9 | C23: Fast Forward | D23: Route Info | E23: Route Info | F23: Detour | G23: Route Info | H23: Road Block | I23: Route Info | P23: 2 | Q23: 3 | R23: Route Info | S23: Fast Forward | T23: Route Info | U23: Detour | V23: Route Info | W23: Road Block | AE23: South Africa | AF23: Southern Africa | AG23: Yes | AJ23: Oswald & Danny | AP23: 3 | AQ23: 3 | AR23: Detour | AS23: Australia | AT23: Central Europe | AU23: Final Leg | AV23: Express Pass
A24: 2 | B24: 10 | C24: Fast Forward | D24: Route Info | E24: Route Info | F24: Detour | G24: Route Info | H24: Road Block | P24: 2 | Q24: 4 | R24: Route Info | S24: Route Info | T24: Fast Forward | U24: Route Info | V24: Route Info | W24: Detour | X24: Route Info | Y24: Route Info | Z24: Road Block | AA24: Route Info | AE24: Namibia | AF24: Southern Africa | AG24: Yes | AJ24: Oswald & Danny | AP24: 4 | AQ24: 4 | AR24: Fast Forward | AS24: Austria | AT24: East Africa | AV24: Head-to-Head
A25: 2 | B25: 11 | C25: Route Info | D25: Fast Forward | E25: Route Info | F25: Detour | G25: Route Info | H25: Road Block | I25: Route Info | P25: 2 | Q25: 5 | R25: Fast Forward | S25: Route Info | T25: Detour | U25: Route Info | V25: Road Block | W25: Route Info | AE25: Thailand | AF25: South East Asia | AG25: Yes | AJ25: Chris & Alex | AP25: 5 | AQ25: 5 | AR25: Speed Bump | AS25: Azerbaijan | AT25: East Asia | AV25: Intersection
A26: 2 | B26: 12 | C26: Route Info | D26: Route Info | E26: Route Info | F26: Detour | G26: Route Info | H26: Road Block | I26: Route Info | P26: 2 | Q26: 6 | R26: Fast Forward | S26: Route Info | T26: Detour | U26: Route Info | V26: Road Block | W26: Route Info | AE26: Thailand | AF26: South East Asia | AG26: No | AJ26: Mary & Peach | AP26: 6 | AQ26: 6 | AR26: Hazard | AS26: Bahrain | AT26: Eastern Europe | AV26: Partner Swap
A27: 2 | B27: Final | C27: Route Info | D27: Route Info | E27: Route Info | F27: Route Info | G27: Route Info | H27: Route Info | I27: Road Block | J27: Route Info | K27: Route Info | P27: 2 | Q27: 7 | R27: Route Info | S27: Route Info | T27: Fast Forward | U27: Route Info | V27: Detour | W27: Route Info | X27: Road Block | Y27: Route Info | AE27: China | AF27: East Asia | AG27: Yes | AJ27: Gary & Dave | AP27: 7 | AQ27: 7 | AR27: Express Pass | AS27: Bangladesh | AT27: Middle East | AV27: Save
A28: 3 | B28: 1 | C28: Route Info | D28: Route Info | E28: Fast Forward | F28: Route Info | G28: Detour | H28: Route Info | P28: 2 | Q28: 8 | R28: Fast Forward | S28: Route Info | T28: Route Info | U28: Detour | V28: Route Info | W28: Road Block | X28: Route Info | AE28: Australia | AF28: Oceania | AG28: No | AJ28: Oswald & Danny | AP28: 8 | AQ28: 8 | AR28: City Sprint | AS28: Barbados | AT28: North America | AV28: Scramble
A29: 3 | B29: 2 | C29: Fast Forward | D29: Route Info | E29: Route Info | F29: Detour | G29: Route Info | H29: Road Block | I29: Route Info | P29: 2 | Q29: 9 | R29: Fast Forward | S29: Route Info | T29: Route Info | U29: Detour | V29: Route Info | W29: Road Block | X29: Route Info | AE29: Australia | AF29: Oceania | AG29: Yes | AJ29: Chris & Alex | AP29: 9 | AQ29: 9 | AR29: Fork-in-Road | AS29: Belgium | AT29: Northern Africa | AV29: U-Turn
A30: 3 | B30: 3 | C30: Fast Forward | D30: Route Info | E30: Detour | F30: Route Info | G30: Road Block | H30: Route Info | P30: 2 | Q30: 10 | R30: Fast Forward | S30: Route Info | T30: Route Info | U30: Detour | V30: Route Info | W30: Road Block | AE30: New Zealand | AF30: Oceania | AG30: No | AJ30: Blake & Paige | AP30: 10 | AQ30: 10 | AS30: Bolivia | AT30: Northern Europe | AV30: Yield
A31: 3 | B31: 4 | C31: Fast Forward | D31: Route Info | E31: Route Info | F31: Detour | G31: Route Info | H31: Road Block | I31: Route Info | P31: 2 | Q31: 11 | R31: Route Info | S31: Fast Forward | T31: Route Info | U31: Detour | V31: Route Info | W31: Road Block | X31: Route Info | AE31: New Zealand | AF31: Oceania | AG31: Yes | AJ31: Tara & Wil | AP31: 11 | AQ31: 11 | AS31: Botswana | AT31: Oceania
A32: 3 | B32: 5 | C32: Fast Forward | D32: Route Info | E32: Detour | F32: Route Info | G32: Route Info | H32: Road Block | I32: Route Info | P32: 2 | Q32: 12 | R32: Route Info | S32: Route Info | T32: Route Info | U32: Detour | V32: Route Info | W32: Road Block | X32: Route Info | AE32: USA | AF32: North America | AG32: No | AJ32: Tara & Wil\nBlake & Paige | AP32: 12 | AQ32: 12 | AS32: Brazil | AT32: South America
A33: 3 | B33: 6 | C33: Route Info | D33: Fast Forward | E33: Route Info | F33: Detour | G33: Route Info | H33: Road Block | I33: Route Info | P33: 2 | Q33: Final | R33: Route Info | S33: Route Info | T33: Route Info | U33: Route Info | V33: Route Info | W33: Route Info | X33: Road Block | Y33: Route Info | Z33: Route Info | AE33: USA | AF33: North America | AG33: Final Leg | AJ33: Chris & Alex | AP33: 13 | AQ33: Final | AS33: Bulgaria | AT33: South Asia
A34: 3 | B34: 7 | C34: Route Info | D34: Fast Forward | E34: Route Info | F34: Detour | G34: Route Info | H34: Road Block | I34: Route Info | P34: 3 | Q34: 1 | R34: Route Info | S34: Route Info | T34: Fast Forward | U34: Route Info | V34: Detour | W34: Route Info | AE34: Mexico | AF34: North America | AG34: Yes | AJ34: Ken & Gerard | AP34: 14 | AS34: Burkina Faso | AT34: South East Asia
A35: 3 | B35: 8 | C35: Route Info | D35: Fast Forward | E35: Route Info | F35: Route Info | G35: Detour | H35: Route Info | I35: Road Block | J35: Route Info | P35: 3 | Q35: 2 | R35: Fast Forward | S35: Route Info | T35: Route Info | U35: Detour | V35: Route Info | W35: Road Block | X35: Route Info | AE35: Mexico | AF35: North America | AG35: Yes | AJ35: Derek & Drew | AP35: 15 | AS35: Cambodia | AT35: Southern Africa
A36: 3 | B36: 9 | C36: Route Info | D36: Fast Forward | E36: Route Info | F36: Detour | G36: Route Info | H36: Road Block | I36: Route Info | P36: 3 | Q36: 3 | R36: Fast Forward | S36: Route Info | T36: Detour | U36: Route Info | V36: Road Block | W36: Route Info | AE36: England\nScotland | AF36: Western Europe\nWestern Europe | AG36: Yes | AJ36: Derek & Drew | AP36: 16 | AS36: Canada | AT36: Southern Europe
A37: 3 | B37: 10 | C37: Route Info | D37: Route Info | E37: Route Info | F37: Route Info | G37: Detour | H37: Fast Forward | I37: Route Info | J37: Road Block | K37: Route Info | P37: 3 | Q37: 4 | R37: Fast Forward | S37: Route Info | T37: Route Info | U37: Detour | V37: Route Info | W37: Road Block | X37: Route Info | AE37: Portugal | AF37: Western Europe | AG37: Yes | AJ37: Ken & Gerard | AP37: 17 | AS37: Chile | AT37: West Africa
A38: 3 | B38: 11 | C38: Route Info | D38: Fast Forward | E38: Route Info | F38: Detour | G38: Route Info | H38: Road Block | P38: 3 | Q38: 5 | R38: Fast Forward | S38: Route Info | T38: Detour | U38: Route Info | V38: Route Info | W38: Road Block | X38: Route Info | AE38: Morocco | AF38: Northern Africa | AG38: Yes | AJ38: Ken & Gerard | AP38: 18 | AS38: China | AT38: West Asia
A39: 3 | B39: 12 | C39: Route Info | D39: Route Info | E39: Detour | F39: Route Info | G39: Road Block | H39: Route Info | P39: 3 | Q39: 6 | R39: Route Info | S39: Fast Forward | T39: Route Info | U39: Detour | V39: Route Info | W39: Road Block | X39: Route Info | AE39: Morocco | AF39: Northern Africa | AG39: Yes | AJ39: Teri & Ian | AP39: 19 | AS39: Colombia | AT39: Western Europe
A40: 3 | B40: Final | C40: Route Info | D40: Route Info | E40: Route Info | F40: Detour | G40: Route Info | H40: Route Info | I40: Route Info | J40: Road Block | K40: Route Info | P40: 3 | Q40: 7 | R40: Route Info | S40: Fast Forward | T40: Route Info | U40: Detour | V40: Route Info | W40: Road Block | X40: Route Info | AE40: Germany\nAustria | AF40: Central Europe\nCentral Europe | AG40: Yes | AJ40: Flo & Zach | AP40: 20 | AS40: Costa Rica
...

Sheet Keywords
B4: Keywords
B6: Keywords are indicators of things that "happened" on each leg of the race. These include common types of challenges and phenomenon that occur during multiple different seasons of TAR.
B8: Definitions: | C8: Legs include:
B9: Animals | C9: challenge(s) that involve riding, herding, and/or working with animals in some way, such as riding an elephant or towing a field with an ox.
B10: Attention to Detail | C10: challenge(s) that involve some level of attention to detail, such as setting a dinner table or locating a specific tile.
B11: Balance | C11: challenge(s) that require team member(s) to balance in some way.
B12: Biking | C12: challenge(s) that require team member(s) to ride any type of bicycle to move around.
B13: Building | C13: challenge(s) that require the assembly of something - provided instructions or otherwise.
B14: Cooking | C14: challenge(s) that require team member(s) to cook something to the acceptance of judges, like cooking fish over a fire, but not necessarily consume it.
B15: Counting | C15: challenge(s) that require team member(s) to count specific things, like beans placed in urns.
B16: Dancing | C16: challenge(s) that require team member(s) to learn choreographed moves to perform for judges, may include routines other than dancing such as color guard or martial arts.
B17: Driving | C17: team member(s) driving some kind of automobile to move around, most commonly driving a car to the next clue, almost always includes navigating.
B18: Flags | C18: challenge(s) that require team member(s) to identify international/domestic flags.
B19: Food | C19: challenge(s) where team member(s) are required to consume food and/or drinks, not applicable for teams voluntarily consuming food and/or drinks.
... B36: Travel Issues | C36: team(s) running into any kind of issues traveling during the leg, such as flight delays, car troubles, getting lost, etc.
C38: *NOTE: many challenges fufill multiple keywords, hopefully in the future I can lay out what keywords apply to each challenge throughout TAR
B40: Keywords Logged per Season:
B41: Seasons | C41: Total | D41: Animals | E41: ATD | F41: Balance | G41: Biking | H41: Building | I41: Cooking | J41: Counting | K41: Dancing | L41: Driving | M41: Flags | N41: Food | O41: Geography | P41: HEC | Q41: Heights | R41: Language | S41: Math | T41: Memory | U41: Music | V41: Navigation | W41: Pain | X41: Painting | Y41: PS | Z41: Puzzle | AA41: Searching | AB41: Selling | AC41: Singing | AD41: Swimming | AE41: Travel Issues
B42: Season 1 | C42: =SUM($D42:$AE42) -> 54 | D42: =COUNTIF(Logs!$Q$9:'Logs'!$AC$17, "*"&D$41&"*") -> 5 | E42: =COUNTIF(Logs!$Q$9:'Logs'!$AC$17, "Attention to Detail") -> 0 | F42: =COUNTIF(Logs!$Q$9:'Logs'!$AC$17, "*"&F$41&"*") -> 0 | G42: =COUNTIF(Logs!$Q$9:'Logs'!$AC$17, "*"&G$41&"*") -> 1 | H42: =COUNTIF(Logs!$Q$9:'Logs'!$AC$17, "*"&H$41&"*") -> 0 | I42: =COUNTIF(Logs!$Q$9:'Logs'!$AC$17, "*"&I$41&"*") -> 0 | J42: =COUNTIF(Logs!$Q$9:'Logs'!$AC$17, "*"&J$41&"*") -> 1 | K42: =COUNTIF(Logs!$Q$9:'Logs'!$AC$17, "*"&K$41&"*") -> 0 | L42: =COUNTIF(Logs!$Q$9:'Logs'!$AC$17, "*"&L$41&"*") -> 5 | M42: =COUNTIF(Logs!$Q$9:'Logs'!$AC$17, "*"&M$41&"*") -> 1 | ... O42: =COUNTIF(Logs!$Q$9:'Logs'!$AC$17, "*"&O$41&"*") -> 0 | P42: =COUNTIF(Logs!$Q$9:'Logs'!$AC$17, "Hand Eye Coordination") -> 1 | Q42: =COUNTIF(Logs!$Q$9:'Logs'!$AC$17, "*"&Q$41&"*") -> 3 | R42: =COUNTIF(Logs!$Q$9:'Logs'!$AC$17, "*"&R$41&"*") -> 2 | S42: =COUNTIF(Logs!$Q$9:'Logs'!$AC$17, "*"&S$41&"*") -> 0 | T42: =COUNTIF(Logs!$Q$9:'Logs'!$AC$17, "Memorization") -> 0 | U42: =COUNTIF(Logs!$Q$9:'Logs'!$AC$17, "*"&U$41&"*") -> 0 | V42: =COUNTIF(Logs!$Q$9:'Logs'!$AC$17, "*"&V$41&"*") -> 3 | W42: =COUNTIF(Logs!$Q$9:'Logs'!$AC$17, W$41) -> 2 | X42: =COUNTIF(Logs!$Q$9:'Logs'!$AC$17, "*"&X$41&"*") -> 0 | Y42: =COUNTIF(Logs!$Q$9:'Logs'!$AC$17, "Physical Strength") -> 7 | Z42: =COUNTIF(Logs!$Q$9:'Logs'!$AC$17, "*"&Z$41&"*") -> 2 | AA42: =COUNTIF(Logs!$Q$9:'Logs'!$AC$17, "*"&AA$41&"*") -> 10 | AB42: =COUNTIF(Logs!$Q$9:'Logs'!$AC$17, "*"&AB$41&"*") -> 0 | AC42: =COUNTIF(Logs!$Q$9:'Logs'!$AC$17, "*"&AC$41&"*") -> 0 | AD42: =COUNTIF(Logs!$Q$9:'Logs'!$AC$17, "*"&AD$41&"*") -> 1 | AE42: =COUNTIF(Logs!$Q$9:'Logs'!$AC$17, "*"&AE$41&"*") -> 9
B43: Season 2 | C43: =SUM($D43:$AE43) -> 57 | D43: =COUNTIF(Logs!$Q$27:'Logs'!$AC$35, "*"&D$41&"*") -> 2 | E43: =COUNTIF(Logs!$Q$27:'Logs'!$AC$35, "Attention to Detail") -> 0 | F43: =COUNTIF(Logs!$Q$27:'Logs'!$AC$35, "*"&F$41&"*") -> 1 | G43: =COUNTIF(Logs!$Q$27:'Logs'!$AC$35, "*"&G$41&"*") -> 1 | H43: =COUNTIF(Logs!$Q$27:'Logs'!$AC$35, "*"&H$41&"*") -> 0 | I43: =COUNTIF(Logs!$Q$27:'Logs'!$AC$35, "*"&I$41&"*") -> 0 | J43: =COUNTIF(Logs!$Q$27:'Logs'!$AC$35, "*"&J$41&"*") -> 0 | K43: =COUNTIF(Logs!$Q$27:'Logs'!$AC$35, "*"&K$41&"*") -> 1 | L43: =COUNTIF(Logs!$Q$27:'Logs'!$AC$35, "*"&L$41&"*") -> 10 | M43: =COUNTIF(Logs!$Q$27:'Logs'!$AC$35, "*"&M$41&"*") -> 0 | ... O43: =COUNTIF(Logs!$Q$27:'Logs'!$AC$35, "*"&O$41&"*") -> 0 | P43: =COUNTIF(Logs!$Q$27:'Logs'!$AC$35, "Hand Eye Coordination") -> 3 | Q43: =COUNTIF(Logs!$Q$27:'Logs'!$AC$35, "*"&Q$41&"*") -> 5 | R43: =COUNTIF(Logs!$Q$27:'Logs'!$AC$35, "*"&R$41&"*") -> 1 | S43: =COUNTIF(Logs!$Q$27:'Logs'!$AC$35, "*"&S$41&"*") -> 0 | T43: =COUNTIF(Logs!$Q$27:'Logs'!$AC$35, "Memorization") -> 0 | U43: =COUNTIF(Logs!$Q$27:'Logs'!$AC$35, "*"&U$41&"*") -> 0 | V43: =COUNTIF(Logs!$Q$27:'Logs'!$AC$35, "*"&V$41&"*") -> 0 | W43: =COUNTIF(Logs!$Q$27:'Logs'!$AC$35,W$41) -> 0 | X43: =COUNTIF(Logs!$Q$27:'Logs'!$AC$35, "*"&X$41&"*") -> 0 | Y43: =COUNTIF(Logs!$Q$27:'Logs'!$AC$35, "Physical Strength") -> 9 | Z43: =COUNTIF(Logs!$Q$27:'Logs'!$AC$35, "*"&Z$41&"*") -> 0 | AA43: =COUNTIF(Logs!$Q$27:'Logs'!$AC$35, "*"&AA$41&"*") -> 8 | AB43: =COUNTIF(Logs!$Q$27:'Logs'!$AC$35, "*"&AB$41&"*") -> 1 | AC43: =COUNTIF(Logs!$Q$27:'Logs'!$AC$35, "*"&AC$41&"*") -> 0 | AD43: =COUNTIF(Logs!$Q$27:'Logs'!$AC$35, "*"&AD$41&"*") -> 2 | AE43: =COUNTIF(Logs!$Q$27:'Logs'!$AC$35, "*"&AE$41&"*") -> 10
B44: Season 3 | C44: =SUM($D44:$AE44) -> 67 | D44: =COUNTIF(Logs!$Q$45:'Logs'!$AC$53, "*"&D$41&"*") -> 3 | E44: =COUNTIF(Logs!$Q$45:'Logs'!$AC$53, "Attention to Detail") -> 1 | F44: =COUNTIF(Logs!$Q$45:'Logs'!$AC$53, "*"&F$41&"*") -> 2 | G44: =COUNTIF(Logs!$Q$45:'Logs'!$AC$53, "*"&G$41&"*") -> 4 | H44: =COUNTIF(Logs!$Q$45:'Logs'!$AC$53, "*"&H$41&"*") -> 1 | I44: =COUNTIF(Logs!$Q$45:'Logs'!$AC$53, "*"&I$41&"*") -> 0 | J44: =COUNTIF(Logs!$Q$45:'Logs'!$AC$53, "*"&J$41&"*") -> 1 | K44: =COUNTIF(Logs!$Q$45:'Logs'!$AC$53, "*"&K$41&"*") -> 0 | L44: =COUNTIF(Logs!$Q$45:'Logs'!$AC$53, "*"&L$41&"*") -> 11 | M44: =COUNTIF(Logs!$Q$45:'Logs'!$AC$53, "*"&M$41&"*") -> 1 | ... O44: =COUNTIF(Logs!$Q$45:'Logs'!$AC$53, "*"&O$41&"*") -> 0 | P44: =COUNTIF(Logs!$Q$45:'Logs'!$AC$53,"Hand Eye Coordination") -> 3 | Q44: =COUNTIF(Logs!$Q$45:'Logs'!$AC$53, "*"&Q$41&"*") -> 6 | R44: =COUNTIF(Logs!$Q$45:'Logs'!$AC$53, "*"&R$41&"*") -> 1 | S44: =COUNTIF(Logs!$Q$45:'Logs'!$AC$53, "*"&S$41&"*") -> 0 | T44: =COUNTIF(Logs!$Q$45:'Logs'!$AC$53, "Memorization") -> 1 | U44: =COUNTIF(Logs!$Q$45:'Logs'!$AC$53, "*"&U$41&"*") -> 0 | V44: =COUNTIF(Logs!$Q$45:'Logs'!$AC$53, "*"&V$41&"*") -> 1 | W44: =COUNTIF(Logs!$Q$45:'Logs'!$AC$53,W$41) -> 0 | X44: =COUNTIF(Logs!$Q$45:'Logs'!$AC$53, "*"&X$41&"*") -> 0 | Y44: =COUNTIF(Logs!$Q$45:'Logs'!$AC$53, "Physical Strength") -> 8 | Z44: =COUNTIF(Logs!$Q$45:'Logs'!$AC$53, "*"&Z$41&"*") -> 0 | AA44: =COUNTIF(Logs!$Q$45:'Logs'!$AC$53, "*"&AA$41&"*") -> 8 | AB44: =COUNTIF(Logs!$Q$45:'Logs'!$AC$53, "*"&AB$41&"*") -> 2 | AC44: =COUNTIF(Logs!$Q$45:'Logs'!$AC$53, "*"&AC$41&"*") -> 0 | AD44: =COUNTIF(Logs!$Q$45:'Logs'!$AC$53, "*"&AD$41&"*") -> 2 | AE44: =COUNTIF(Logs!$Q$45:'Logs'!$AC$53, "*"&AE$41&"*") -> 10
B45: Season 4 | C45: =SUM($D45:$AE45) -> 58 | D45: =COUNTIF(Logs!$Q$63:'Logs'!$AC$71, "*"&D$41&"*") -> 6 | E45: =COUNTIF(Logs!$Q$63:'Logs'!$AC$71, "Attention to Detail") -> 0 | F45: =COUNTIF(Logs!$Q$63:'Logs'!$AC$71, "*"&F$41&"*") -> 1 | G45: =COUNTIF(Logs!$Q$63:'Logs'!$AC$71, "*"&G$41&"*") -> 2 | H45: =COUNTIF(Logs!$Q$63:'Logs'!$AC$71, "*"&H$41&"*") -> 0 | I45: =COUNTIF(Logs!$Q$63:'Logs'!$AC$71, "*"&I$41&"*") -> 0 | J45: =COUNTIF(Logs!$Q$63:'Logs'!$AC$71, "*"&J$41&"*") -> 0 | K45: =COUNTIF(Logs!$Q$63:'Logs'!$AC$71, "*"&K$41&"*") -> 0 | L45: =COUNTIF(Logs!$Q$63:'Logs'!$AC$71, "*"&L$41&"*") -> 6 | M45: =COUNTIF(Logs!$Q$63:'Logs'!$AC$71, "*"&M$41&"*") -> 0 | ... O45: =COUNTIF(Logs!$Q$63:'Logs'!$AC$71, "*"&O$41&"*") -> 0 | P45: =COUNTIF(Logs!$Q$63:'Logs'!$AC$71,"Hand Eye Coordination") -> 1 | Q45: =COUNTIF(Logs!$Q$63:'Logs'!$AC$71, "*"&Q$41&"*") -> 6 | R45: =COUNTIF(Logs!$Q$63:'Logs'!$AC$71, "*"&R$41&"*") -> 0 | S45: =COUNTIF(Logs!$Q$63:'Logs'!$AC$71, "*"&S$41&"*") -> 0 | T45: =COUNTIF(Logs!$Q$63:'Logs'!$AC$71, "Memorization") -> 0 | U45: =COUNTIF(Logs!$Q$63:'Logs'!$AC$71, "*"&U$41&"*") -> 0 | V45: =COUNTIF(Logs!$Q$63:'Logs'!$AC$71, "*"&V$41&"*") -> 3 | W45: =COUNTIF(Logs!$Q$63:'Logs'!$AC$71, W$41) -> 2 | X45: =COUNTIF(Logs!$Q$63:'Logs'!$AC$71, "*"&X$41&"*") -> 0 | Y45: =COUNTIF(Logs!$Q$63:'Logs'!$AC$71, "Physical Strength") -> 9 | Z45: =COUNTIF(Logs!$Q$63:'Logs'!$AC$71, "*"&Z$41&"*") -> 2 | AA45: =COUNTIF(Logs!$Q$63:'Logs'!$AC$71, "*"&AA$41&"*") -> 7 | AB45: =COUNTIF(Logs!$Q$63:'Logs'!$AC$71, "*"&AB$41&"*") -> 0 | AC45: =COUNTIF(Logs!$Q$63:'Logs'!$AC$71, "*"&AC$41&"*") -> 0 | AD45: =COUNTIF(Logs!$Q$63:'Logs'!$AC$71, "*"&AD$41&"*") -> 3 | AE45: =COUNTIF(Logs!$Q$63:'Logs'!$AC$71, "*"&AE$41&"*") -> 9 | AG45: Keywords Logged per Leg:
B46: Season 5 | C46: =SUM($D46:$AE46) -> 63 | D46: =COUNTIF(Logs!$Q$81:'Logs'!$AC$88, "*"&D$41&"*") -> 6 | E46: =COUNTIF(Logs!$Q$81:'Logs'!$AC$88, "Attention to Detail") -> 1 | F46: =COUNTIF(Logs!$Q$81:'Logs'!$AC$88, "*"&F$41&"*") -> 0 | G46: =COUNTIF(Logs!$Q$81:'Logs'!$AC$88, "*"&G$41&"*") -> 3 | H46: =COUNTIF(Logs!$Q$81:'Logs'!$AC$88, "*"&H$41&"*") -> 0 | I46: =COUNTIF(Logs!$Q$81:'Logs'!$AC$88, "*"&I$41&"*") -> 1 | J46: =COUNTIF(Logs!$Q$81:'Logs'!$AC$88, "*"&J$41&"*") -> 0 | K46: =COUNTIF(Logs!$Q$81:'Logs'!$AC$88, "*"&K$41&"*") -> 0 | L46: =COUNTIF(Logs!$Q$81:'Logs'!$AC$88, "*"&L$41&"*") -> 8 | M46: =COUNTIF(Logs!$Q$81:'Logs'!$AC$88, "*"&M$41&"*") -> 1 | ... O46: =COUNTIF(Logs!$Q$81:'Logs'!$AC$88, "*"&O$41&"*") -> 0 | P46: =COUNTIF(Logs!$Q$81:'Logs'!$AC$88,"Hand Eye Coordination") -> 1 | Q46: =COUNTIF(Logs!$Q$81:'Logs'!$AC$88, "*"&Q$41&"*") -> 6 | R46: =COUNTIF(Logs!$Q$81:'Logs'!$AC$88, "*"&R$41&"*") -> 0 | S46: =COUNTIF(Logs!$Q$81:'Logs'!$AC$88, "*"&S$41&"*") -> 0 | T46: =COUNTIF(Logs!$Q$81:'Logs'!$AC$88, "Memorization") -> 0 | U46: =COUNTIF(Logs!$Q$81:'Logs'!$AC$88, "*"&U$41&"*") -> 0 | V46: =COUNTIF(Logs!$Q$81:'Logs'!$AC$88, "*"&V$41&"*") -> 2 | W46: =COUNTIF(Logs!$Q$81:'Logs'!$AC$88, W$41) -> 1 | X46: =COUNTIF(Logs!$Q$81:'Logs'!$AC$88, "*"&X$41&"*") -> 0 | Y46: =COUNTIF(Logs!$Q$81:'Logs'!$AC$88, "Physical Strength") -> 10 | Z46: =COUNTIF(Logs!$Q$81:'Logs'!$AC$88, "*"&Z$41&"*") -> 1 | AA46: =COUNTIF(Logs!$Q$81:'Logs'!$AC$88, "*"&AA$41&"*") -> 6 | AB46: =COUNTIF(Logs!$Q$81:'Logs'!$AC$88, "*"&AB$41&"*") -> 0 | AC46: =COUNTIF(Logs!$Q$81:'Logs'!$AC$88, "*"&AC$41&"*") -> 0 | AD46: =COUNTIF(Logs!$Q$81:'Logs'!$AC$88, "*"&AD$41&"*") -> 2 | AE46: =COUNTIF(Logs!$Q$81:'Logs'!$AC$88, "*"&AE$41&"*") -> 11 | AG46: Leg # | AH46: Animals | AI46: ATD | AJ46: Balance | AK46: Biking | AL46: Building | AM46: Cooking | AN46: Counting | AO46: Dancing | AP46: Driving | AQ46: Flags | AR46: Food | AS46: Geography | AT46: Hand Eye Coordination | AU46: Heights | AV46: Language | AW46: Math | AX46: Memorization | AY46: Music | AZ46: Navigation | BA46: Pain | BB46: Painting | BC46: Physical Strength | BD46: Puzzle | BE46: Searching | BF46: Selling | BG46: Singing | BH46: Swimming | BI46: Travel Issues | BJ46: Totals
B47: Season 6 | C47: =SUM($D47:$AE47) -> 61 | D47: =COUNTIF(Logs!$Q$101:'Logs'!$AB$110, "*"&D$41&"*") -> 3 | E47: =COUNTIF(Logs!$Q$101:'Logs'!$AB$110, "Attention to Detail") -> 2 | F47: =COUNTIF(Logs!$Q$101:'Logs'!$AB$110, "*"&F$41&"*") -> 2 | G47: =COUNTIF(Logs!$Q$101:'Logs'!$AB$110, "*"&G$41&"*") -> 2 | H47: =COUNTIF(Logs!$Q$101:'Logs'!$AB$110, "*"&H$41&"*") -> 1 | I47: =COUNTIF(Logs!$Q$101:'Logs'!$AB$110, "*"&I$41&"*") -> 1 | J47: =COUNTIF(Logs!$Q$101:'Logs'!$AB$110, "*"&J$41&"*") -> 1 | K47: =COUNTIF(Logs!$Q$101:'Logs'!$AB$110, "*"&K$41&"*") -> 0 | L47: =COUNTIF(Logs!$Q$101:'Logs'!$AB$110, "*"&L$41&"*") -> 7 | M47: =COUNTIF(Logs!$Q$101:'Logs'!$AB$110, "*"&M$41&"*") -> 0 | ... O47: =COUNTIF(Logs!$Q$101:'Logs'!$AB$110, "*"&O$41&"*") -> 0 | P47: =COUNTIF(Logs!$Q$101:'Logs'!$AB$110, "Hand Eye Coordination") -> 3 | Q47: =COUNTIF(Logs!$Q$101:'Logs'!$AB$110, "*"&Q$41&"*") -> 5 | R47: =COUNTIF(Logs!$Q$101:'Logs'!$AB$110, "*"&R$41&"*") -> 0 | S47: =COUNTIF(Logs!$Q$101:'Logs'!$AB$110, "*"&S$41&"*") -> 0 | T47: =COUNTIF(Logs!$Q$101:'Logs'!$AB$110, "Memorization") -> 0 | U47: =COUNTIF(Logs!$Q$101:'Logs'!$AB$110, "*"&U$41&"*") -> 0 | V47: =COUNTIF(Logs!$Q$101:'Logs'!$AB$110, "*"&V$41&"*") -> 2 | W47: =COUNTIF(Logs!$Q$101:'Logs'!$AB$110,W$41) -> 0 | X47: =COUNTIF(Logs!$Q$101:'Logs'!$AB$110, "*"&X$41&"*") -> 1 | Y47: =COUNTIF(Logs!$Q$101:'Logs'!$AB$110, "Physical Strength") -> 10 | Z47: =COUNTIF(Logs!$Q$101:'Logs'!$AB$110, "*"&Z$41&"*") -> 0 | AA47: =COUNTIF(Logs!$Q$101:'Logs'!$AB$110, "*"&AA$41&"*") -> 7 | AB47: =COUNTIF(Logs!$Q$101:'Logs'!$AB$110, "*"&AB$41&"*") -> 0 | AC47: =COUNTIF(Logs!$Q$101:'Logs'!$AB$110, "*"&AC$41&"*") -> 0 | AD47: =COUNTIF(Logs!$Q$101:'Logs'!$AB$110, "*"&AD$41&"*") -> 3 | AE47: =COUNTIF(Logs!$Q$101:'Logs'!$AB$110, "*"&AE$41&"*") -> 8 | AG47: Leg 1 | AH47: =COUNTIF(Logs!$Q$9:'Logs'!$Q$1001, "*"&AH$46&"*") -> 5 | AI47: =COUNTIF(Logs!$Q$9:'Logs'!$Q$1001, "Attention to Detail") -> 10 | AJ47: =COUNTIF(Logs!$Q$9:'Logs'!$Q$1001, "*"&AJ$46&"*") -> 4 | AK47: =COUNTIF(Logs!$Q$9:'Logs'!$Q$1001, "*"&AK$46&"*") -> 2 | AL47: =COUNTIF(Logs!$Q$9:'Logs'!$Q$1001, "*"&AL$46&"*") -> 3 | AM47: =COUNTIF(Logs!$Q$9:'Logs'!$Q$1001, "*"&AM$46&"*") -> 1 | AN47: =COUNTIF(Logs!$Q$9:'Logs'!$Q$1001, "*"&AN$46&"*") -> 0 | AO47: =COUNTIF(Logs!$Q$9:'Logs'!$Q$1001, "*"&AO$46&"*") -> 4 | AP47: =COUNTIF(Logs!$Q$9:'Logs'!$Q$1001, "*"&AP$46&"*") -> 24 | AQ47: =COUNTIF(Logs!$Q$9:'Logs'!$Q$1001, "*"&AQ$46&"*") -> 1 | ... AZ47: =COUNTIF(Logs!$Q$9:'Logs'!$Q$1001, "*"&AZ$46&"*") -> 1 | BA47: =COUNTIF(Logs!$Q$9:'Logs'!$Q$1001, BA$46) -> 2 | BB47: =COUNTIF(Logs!$Q$9:'Logs'!$Q$1001, "*"&BB$46&"*") -> 1 | BC47: =COUNTIF(Logs!$Q$9:'Logs'!$Q$1001, "*"&BC$46&"*") -> 29 | BD47: =COUNTIF(Logs!$Q$9:'Logs'!$Q$1001, "*"&BD$46&"*") -> 7 | BE47: =COUNTIF(Logs!$Q$9:'Logs'!$Q$1001, "*"&BE$46&"*") -> 22 | BF47: =COUNTIF(Logs!$Q$9:'Logs'!$Q$1001, "*"&BF$46&"*") -> 1 | BG47: =COUNTIF(Logs!$Q$9:'Logs'!$Q$1001, "*"&BG$46&"*") -> 1 | BH47: =COUNTIF(Logs!$Q$9:'Logs'!$Q$1001, "*"&BH$46&"*") -> 0 | BI47: =COUNTIF(Logs!$Q$9:'Logs'!$Q$1001, "*"&BI$46&"*") -> 30 | BJ47: =SUM(Table37[[#This Row],[Animals]:[Travel Issues]]) -> 185
B48: Season 7 | C48: =SUM($D48:$AE48) -> 55 | D48: =COUNTIF(Logs!$Q$120:'Logs'!$AC$128, "*"&D$41&"*") -> 5 | E48: =COUNTIF(Logs!$Q$120:'Logs'!$AC$128, "Attention to Detail") -> 1 | F48: =COUNTIF(Logs!$Q$120:'Logs'!$AC$128, "*"&F$41&"*") -> 2 | G48: =COUNTIF(Logs!$Q$120:'Logs'!$AC$128, "*"&G$41&"*") -> 1 | H48: =COUNTIF(Logs!$Q$120:'Logs'!$AC$128, "*"&H$41&"*") -> 1 | I48: =COUNTIF(Logs!$Q$120:'Logs'!$AC$128, "*"&I$41&"*") -> 0 | J48: =COUNTIF(Logs!$Q$120:'Logs'!$AC$128, "*"&J$41&"*") -> 0 | K48: =COUNTIF(Logs!$Q$120:'Logs'!$AC$128, "*"&K$41&"*") -> 0 | L48: =COUNTIF(Logs!$Q$120:'Logs'!$AC$128, "*"&L$41&"*") -> 8 | M48: =COUNTIF(Logs!$Q$120:'Logs'!$AC$128, "*"&M$41&"*") -> 0 | ... O48: =COUNTIF(Logs!$Q$120:'Logs'!$AC$128, "*"&O$41&"*") -> 0 | P48: =COUNTIF(Logs!$Q$120:'Logs'!$AC$128, "Hand Eye Coordination") -> 2 | Q48: =COUNTIF(Logs!$Q$120:'Logs'!$AC$128, "*"&Q$41&"*") -> 4 | R48: =COUNTIF(Logs!$Q$120:'Logs'!$AC$128, "*"&R$41&"*") -> 0 | S48: =COUNTIF(Logs!$Q$120:'Logs'!$AC$128, "*"&S$41&"*") -> 0 | T48: =COUNTIF(Logs!$Q$120:'Logs'!$AC$128, "Memorization") -> 0 | U48: =COUNTIF(Logs!$Q$120:'Logs'!$AC$128, "*"&U$41&"*") -> 0 | V48: =COUNTIF(Logs!$Q$120:'Logs'!$AC$128, "*"&V$41&"*") -> 2 | W48: =COUNTIF(Logs!$Q$120:'Logs'!$AC$128, W$41) -> 1 | X48: =COUNTIF(Logs!$Q$120:'Logs'!$AC$128, "*"&X$41&"*") -> 0 | Y48: =COUNTIF(Logs!$Q$120:'Logs'!$AC$128, "Physical Strength") -> 7 | Z48: =COUNTIF(Logs!$Q$120:'Logs'!$AC$128, "*"&Z$41&"*") -> 1 | AA48: =COUNTIF(Logs!$Q$120:'Logs'!$AC$128, "*"&AA$41&"*") -> 8 | AB48: =COUNTIF(Logs!$Q$120:'Logs'!$AC$128, "*"&AB$41&"*") -> 1 | AC48: =COUNTIF(Logs!$Q$120:'Logs'!$AC$128, "*"&AC$41&"*") -> 0 | AD48: =COUNTIF(Logs!$Q$120:'Logs'!$AC$128, "*"&AD$41&"*") -> 1 | AE48: =COUNTIF(Logs!$Q$120:'Logs'!$AC$128, "*"&AE$41&"*") -> 9 | AG48: Leg 2 | AH48: =COUNTIF(Logs!$R$9:'Logs'!$R$1001, "*"&AH$46&"*") -> 6 | AI48: =COUNTIF(Logs!$R$9:'Logs'!$R$1001, "Attention to Detail") -> 18 | AJ48: =COUNTIF(Logs!$R$9:'Logs'!$R$1001, "*"&AJ$46&"*") -> 5 | AK48: =COUNTIF(Logs!$R$9:'Logs'!$R$1001, "*"&AK$46&"*") -> 1 | AL48: =COUNTIF(Logs!$R$9:'Logs'!$R$1001, "*"&AL$46&"*") -> 6 | AM48: =COUNTIF(Logs!$R$9:'Logs'!$R$1001, "*"&AM$46&"*") -> 3 | AN48: =COUNTIF(Logs!$R$9:'Logs'!$R$1001, "*"&AN$46&"*") -> 0 | AO48: =COUNTIF(Logs!$R$9:'Logs'!$R$1001, "*"&AO$46&"*") -> 4 | AP48: =COUNTIF(Logs!$R$9:'Logs'!$R$1001, "*"&AP$46&"*") -> 14 | AQ48: =COUNTIF(Logs!$R$9:'Logs'!$R$1001, "*"&AQ$46&"*") -> 1 | ... AZ48: =COUNTIF(Logs!$R$9:'Logs'!$R$1001, "*"&AZ$46&"*") -> 2 | BA48: =COUNTIF(Logs!$R$9:'Logs'!$R$1001, BA$46) -> 1 | BB48: =COUNTIF(Logs!$R$9:'Logs'!$R$1001, "*"&BB$46&"*") -> 2 | BC48: =COUNTIF(Logs!$R$9:'Logs'!$R$1001, "*"&BC$46&"*") -> 26 | BD48: =COUNTIF(Logs!$R$9:'Logs'!$R$1001, "*"&BD$46&"*") -> 5 | BE48: =COUNTIF(Logs!$R$9:'Logs'!$R$1001, "*"&BE$46&"*") -> 22 | BF48: =COUNTIF(Logs!$R$9:'Logs'!$R$1001, "*"&BF$46&"*") -> 1 | BG48: =COUNTIF(Logs!$R$9:'Logs'!$R$1001, "*"&BG$46&"*") -> 1 | BH48: =COUNTIF(Logs!$R$9:'Logs'!$R$1001, "*"&BH$46&"*") -> 3 | BI48: =COUNTIF(Logs!$R$9:'Logs'!$R$1001, "*"&BI$46&"*") -> 27 | BJ48: =SUM(Table37[[#This Row],[Animals]:[Travel Issues]]) -> 175
B49: Season 8 | C49: =SUM($D49:$AE49) -> 56 | D49: =COUNTIF(Logs!$Q$139:'Logs'!$AC$147, "*"&D$41&"*") -> 2 | E49: =COUNTIF(Logs!$Q$139:'Logs'!$AC$147, "Attention to Detail") -> 3 | F49: =COUNTIF(Logs!$Q$139:'Logs'!$AC$147, "*"&F$41&"*") -> 0 | G49: =COUNTIF(Logs!$Q$139:'Logs'!$AC$147, "*"&G$41&"*") -> 2 | H49: =COUNTIF(Logs!$Q$139:'Logs'!$AC$147, "*"&H$41&"*") -> 3 | I49: =COUNTIF(Logs!$Q$139:'Logs'!$AC$147, "*"&I$41&"*") -> 1 | J49: =COUNTIF(Logs!$Q$139:'Logs'!$AC$147, "*"&J$41&"*") -> 0 | K49: =COUNTIF(Logs!$Q$139:'Logs'!$AC$147, "*"&K$41&"*") -> 0 | L49: =COUNTIF(Logs!$Q$139:'Logs'!$AC$147, "*"&L$41&"*") -> 11 | M49: =COUNTIF(Logs!$Q$139:'Logs'!$AC$147, "*"&M$41&"*") -> 0 | ... O49: =COUNTIF(Logs!$Q$139:'Logs'!$AC$147, "*"&O$41&"*") -> 1 | P49: =COUNTIF(Logs!$Q$139:'Logs'!$AC$147, "Hand Eye Coordination") -> 2 | Q49: =COUNTIF(Logs!$Q$139:'Logs'!$AC$147, "*"&Q$41&"*") -> 4 | R49: =COUNTIF(Logs!$Q$139:'Logs'!$AC$147, "*"&R$41&"*") -> 0 | S49: =COUNTIF(Logs!$Q$139:'Logs'!$AC$147, "*"&S$41&"*") -> 0 | T49: =COUNTIF(Logs!$Q$139:'Logs'!$AC$147, "Memorization") -> 0 | U49: =COUNTIF(Logs!$Q$139:'Logs'!$AC$147, "*"&U$41&"*") -> 0 | V49: =COUNTIF(Logs!$Q$139:'Logs'!$AC$147, "*"&V$41&"*") -> 1 | W49: =COUNTIF(Logs!$Q$139:'Logs'!$AC$147, W$41) -> 1 | X49: =COUNTIF(Logs!$Q$139:'Logs'!$AC$147, "*"&X$41&"*") -> 1 | Y49: =COUNTIF(Logs!$Q$139:'Logs'!$AC$147, "Physical Strength") -> 10 | Z49: =COUNTIF(Logs!$Q$139:'Logs'!$AC$147, "*"&Z$41&"*") -> 0 | AA49: =COUNTIF(Logs!$Q$139:'Logs'!$AC$147, "*"&AA$41&"*") -> 6 | AB49: =COUNTIF(Logs!$Q$139:'Logs'!$AC$147, "*"&AB$41&"*") -> 0 | AC49: =COUNTIF(Logs!$Q$139:'Logs'!$AC$147, "*"&AC$41&"*") -> 0 | AD49: =COUNTIF(Logs!$Q$139:'Logs'!$AC$147, "*"&AD$41&"*") -> 1 | AE49: =COUNTIF(Logs!$Q$139:'Logs'!$AC$147, "*"&AE$41&"*") -> 7 | AG49: Leg 3 | AH49: =COUNTIF(Logs!$S$9:'Logs'!$S$1001, "*"&AH$46&"*") -> 7 | AI49: =COUNTIF(Logs!$S$9:'Logs'!$S$1001, "Attention to Detail") -> 18 | AJ49: =COUNTIF(Logs!$S$9:'Logs'!$S$1001, "*"&AJ$46&"*") -> 6 | AK49: =COUNTIF(Logs!$S$9:'Logs'!$S$1001, "*"&AK$46&"*") -> 7 | AL49: =COUNTIF(Logs!$S$9:'Logs'!$S$1001, "*"&AL$46&"*") -> 5 | AM49: =COUNTIF(Logs!$S$9:'Logs'!$S$1001, "*"&AM$46&"*") -> 5 | AN49: =COUNTIF(Logs!$S$9:'Logs'!$S$1001, "*"&AN$46&"*") -> 1 | AO49: =COUNTIF(Logs!$S$9:'Logs'!$S$1001, "*"&AO$46&"*") -> 7 | AP49: =COUNTIF(Logs!$S$9:'Logs'!$S$1001, "*"&AP$46&"*") -> 14 | AQ49: =COUNTIF(Logs!$S$9:'Logs'!$S$1001, "*"&AQ$46&"*") -> 0 | ... AZ49: =COUNTIF(Logs!$S$9:'Logs'!$S$1001, "*"&AZ$46&"*") -> 1 | BA49: =COUNTIF(Logs!$S$9:'Logs'!$S$1001, BA$46) -> 2 | BB49: =COUNTIF(Logs!$S$9:'Logs'!$S$1001, "*"&BB$46&"*") -> 0 | BC49: =COUNTIF(Logs!$S$9:'Logs'!$S$1001, "*"&BC$46&"*") -> 25 | BD49: =COUNTIF(Logs!$S$9:'Logs'!$S$1001, "*"&BD$46&"*") -> 4 | BE49: =COUNTIF(Logs!$S$9:'Logs'!$S$1001, "*"&BE$46&"*") -> 14 | BF49: =COUNTIF(Logs!$S$9:'Logs'!$S$1001, "*"&BF$46&"*") -> 2 | BG49: =COUNTIF(Logs!$S$9:'Logs'!$S$1001, "*"&BG$46&"*") -> 1 | BH49: =COUNTIF(Logs!$S$9:'Logs'!$S$1001, "*"&BH$46&"*") -> 1 | BI49: =COUNTIF(Logs!$S$9:'Logs'!$S$1001, "*"&BI$46&"*") -> 28 | BJ49: =SUM(Table37[[#This Row],[Animals]:[Travel Issues]]) -> 176
B50: Season 9 | C50: =SUM($D50:$AE50) -> 66 | D50: =COUNTIF(Logs!$Q$159:'Logs'!$AC$167, "*"&D$41&"*") -> 3 | E50: =COUNTIF(Logs!$Q$159:'Logs'!$AC$167, "Attention to Detail") -> 2 | F50: =COUNTIF(Logs!$Q$159:'Logs'!$AC$167, "*"&F$41&"*") -> 1 | G50: =COUNTIF(Logs!$Q$159:'Logs'!$AC$167, "*"&G$41&"*") -> 2 | H50: =COUNTIF(Logs!$Q$159:'Logs'!$AC$167, "*"&H$41&"*") -> 3 | I50: =COUNTIF(Logs!$Q$159:'Logs'!$AC$167, "*"&I$41&"*") -> 0 | J50: =COUNTIF(Logs!$Q$159:'Logs'!$AC$167, "*"&J$41&"*") -> 1 | K50: =COUNTIF(Logs!$Q$159:'Logs'!$AC$167, "*"&K$41&"*") -> 1 | L50: =COUNTIF(Logs!$Q$159:'Logs'!$AC$167, "*"&L$41&"*") -> 11 | M50: =COUNTIF(Logs!$Q$159:'Logs'!$AC$167, "*"&M$41&"*") -> 1 | ... O50: =COUNTIF(Logs!$Q$159:'Logs'!$AC$167, "*"&O$41&"*") -> 0 | P50: =COUNTIF(Logs!$Q$159:'Logs'!$AC$167, "Hand Eye Coordination") -> 1 | Q50: =COUNTIF(Logs!$Q$159:'Logs'!$AC$167, "*"&Q$41&"*") -> 4 | R50: =COUNTIF(Logs!$Q$159:'Logs'!$AC$167, "*"&R$41&"*") -> 1 | S50: =COUNTIF(Logs!$Q$159:'Logs'!$AC$167, "*"&S$41&"*") -> 0 | T50: =COUNTIF(Logs!$Q$159:'Logs'!$AC$167, "Memorization") -> 1 | U50: =COUNTIF(Logs!$Q$159:'Logs'!$AC$167, "*"&U$41&"*") -> 1 | V50: =COUNTIF(Logs!$Q$159:'Logs'!$AC$167, "*"&V$41&"*") -> 0 | W50: =COUNTIF(Logs!$Q$159:'Logs'!$AC$167, W$41) -> 1 | X50: =COUNTIF(Logs!$Q$159:'Logs'!$AC$167, "*"&X$41&"*") -> 0 | Y50: =COUNTIF(Logs!$Q$159:'Logs'!$AC$167, "Physical Strength") -> 9 | Z50: =COUNTIF(Logs!$Q$159:'Logs'!$AC$167, "*"&Z$41&"*") -> 1 | AA50: =COUNTIF(Logs!$Q$159:'Logs'!$AC$167, "*"&AA$41&"*") -> 8 | AB50: =COUNTIF(Logs!$Q$159:'Logs'!$AC$167, "*"&AB$41&"*") -> 1 | AC50: =COUNTIF(Logs!$Q$159:'Logs'!$AC$167, "*"&AC$41&"*") -> 0 | AD50: =COUNTIF(Logs!$Q$159:'Logs'!$AC$167, "*"&AD$41&"*") -> 2 | AE50: =COUNTIF(Logs!$Q$159:'Logs'!$AC$167, "*"&AE$41&"*") -> 10 | AG50: Leg 4 | AH50: =COUNTIF(Logs!$T$9:'Logs'!$T$1001, "*"&AH$46&"*") -> 9 | AI50: =COUNTIF(Logs!$T$9:'Logs'!$T$1001, "Attention to Detail") -> 20 | AJ50: =COUNTIF(Logs!$T$9:'Logs'!$T$1001, "*"&AJ$46&"*") -> 2 | AK50: =COUNTIF(Logs!$T$9:'Logs'!$T$1001, "*"&AK$46&"*") -> 3 | AL50: =COUNTIF(Logs!$T$9:'Logs'!$T$1001, "*"&AL$46&"*") -> 12 | AM50: =COUNTIF(Logs!$T$9:'Logs'!$T$1001, "*"&AM$46&"*") -> 2 | AN50: =COUNTIF(Logs!$T$9:'Logs'!$T$1001, "*"&AN$46&"*") -> 1 | AO50: =COUNTIF(Logs!$T$9:'Logs'!$T$1001, "*"&AO$46&"*") -> 4 | AP50: =COUNTIF(Logs!$T$9:'Logs'!$T$1001, "*"&AP$46&"*") -> 17 | AQ50: =COUNTIF(Logs!$T$9:'Logs'!$T$1001, "*"&AQ$46&"*") -> 2 | ... AZ50: =COUNTIF(Logs!$T$9:'Logs'!$T$1001, "*"&AZ$46&"*") -> 3 | BA50: =COUNTIF(Logs!$T$9:'Logs'!$T$1001,BA$46) -> 3 | BB50: =COUNTIF(Logs!$T$9:'Logs'!$T$1001, "*"&BB$46&"*") -> 0 | BC50: =COUNTIF(Logs!$T$9:'Logs'!$T$1001, "*"&BC$46&"*") -> 27 | BD50: =COUNTIF(Logs!$T$9:'Logs'!$T$1001, "*"&BD$46&"*") -> 9 | BE50: =COUNTIF(Logs!$T$9:'Logs'!$T$1001, "*"&BE$46&"*") -> 13 | BF50: =COUNTIF(Logs!$T$9:'Logs'!$T$1001, "*"&BF$46&"*") -> 1 | BG50: =COUNTIF(Logs!$T$9:'Logs'!$T$1001, "*"&BG$46&"*") -> 0 | BH50: =COUNTIF(Logs!$T$9:'Logs'!$T$1001, "*"&BH$46&"*") -> 2 | BI50: =COUNTIF(Logs!$T$9:'Logs'!$T$1001, "*"&BI$46&"*") -> 20 | BJ50: =SUM(Table37[[#This Row],[Animals]:[Travel Issues]]) -> 180
